<?xml version="1.0" ?>
<robot name="arm" xmlns:xacro="http://www.ros.org/wiki/xacro">

<xacro:include filename="$(find arm_description)/urdf/materials.xacro" />
<xacro:include filename="$(find arm_description)/urdf/arm.trans" />
<xacro:include filename="$(find arm_description)/urdf/arm.gazebo" />
<link name="base_link">
  <inertial>
    <origin xyz="0.0 -1.4925041259863438e-17 0.06499999999999999" rpy="0 0 0"/>
    <mass value="38.26875"/>
    <inertia ixx="0.125649" iyy="0.253212" izz="0.27107" ixy="-0.0" iyz="-0.0" ixz="-0.0"/>
  </inertial>
  <visual>
    <origin xyz="0 0 0" rpy="0 0 0"/>
    <geometry>
      <mesh filename="file://$(find arm_description)/meshes/base_link.stl" scale="0.001 0.001 0.001"/>
    </geometry>
    <material name="silver"/>
  </visual>
  <collision>
    <origin xyz="0 0 0" rpy="0 0 0"/>
    <geometry>
      <mesh filename="file://$(find arm_description)/meshes/base_link.stl" scale="0.001 0.001 0.001"/>
    </geometry>
  </collision>
</link>

<link name="link_1_1">
  <inertial>
    <origin xyz="0.0 -1.9172293647565634e-17 0.044466790992911065" rpy="0 0 0"/>
    <mass value="29.791045516659985"/>
    <inertia ixx="0.126725" iyy="0.177006" izz="0.260409" ixy="-0.0" iyz="-0.0" ixz="-0.0"/>
  </inertial>
  <visual>
    <origin xyz="-0.0 0.0 -0.13" rpy="0 0 0"/>
    <geometry>
      <mesh filename="file://$(find arm_description)/meshes/link_1_1.stl" scale="0.001 0.001 0.001"/>
    </geometry>
    <material name="silver"/>
  </visual>
  <collision>
    <origin xyz="-0.0 0.0 -0.13" rpy="0 0 0"/>
    <geometry>
      <mesh filename="file://$(find arm_description)/meshes/link_1_1.stl" scale="0.001 0.001 0.001"/>
    </geometry>
  </collision>
</link>

<link name="link_2_1">
  <inertial>
    <origin xyz="-0.02500000000000002 -0.00020598185767762808 0.15763545013473024" rpy="0 0 0"/>
    <mass value="5.4333462441733"/>
    <inertia ixx="0.05532" iyy="0.05572" izz="0.001864" ixy="-0.0" iyz="-1e-06" ixz="-0.0"/>
  </inertial>
  <visual>
    <origin xyz="-0.025 0.0 -0.187" rpy="0 0 0"/>
    <geometry>
      <mesh filename="file://$(find arm_description)/meshes/link_2_1.stl" scale="0.001 0.001 0.001"/>
    </geometry>
    <material name="silver"/>
  </visual>
  <collision>
    <origin xyz="-0.025 0.0 -0.187" rpy="0 0 0"/>
    <geometry>
      <mesh filename="file://$(find arm_description)/meshes/link_2_1.stl" scale="0.001 0.001 0.001"/>
    </geometry>
  </collision>
</link>

<link name="link_3_1">
  <inertial>
    <origin xyz="-0.020000000000000018 1.8021706576164774e-07 0.2049579836943658" rpy="0 0 0"/>
    <mass value="5.602676995338638"/>
    <inertia ixx="0.09396" iyy="0.093954" izz="0.0015" ixy="-0.0" iyz="0.0" ixz="0.0"/>
  </inertial>
  <visual>
    <origin xyz="0.025 0.000205 -0.499621" rpy="0 0 0"/>
    <geometry>
      <mesh filename="file://$(find arm_description)/meshes/link_3_1.stl" scale="0.001 0.001 0.001"/>
    </geometry>
    <material name="silver"/>
  </visual>
  <collision>
    <origin xyz="0.025 0.000205 -0.499621" rpy="0 0 0"/>
    <geometry>
      <mesh filename="file://$(find arm_description)/meshes/link_3_1.stl" scale="0.001 0.001 0.001"/>
    </geometry>
  </collision>
</link>

<link name="link_4_1">
  <inertial>
    <origin xyz="0.028999999999999988 1.8021706575785303e-07 0.048622111514249" rpy="0 0 0"/>
    <mass value="3.001091821620515"/>
    <inertia ixx="0.004114" iyy="0.004104" izz="0.001692" ixy="-0.0" iyz="-0.0" ixz="-0.0"/>
  </inertial>
  <visual>
    <origin xyz="0.025 0.000205 -0.919071" rpy="0 0 0"/>
    <geometry>
      <mesh filename="file://$(find arm_description)/meshes/link_4_1.stl" scale="0.001 0.001 0.001"/>
    </geometry>
    <material name="silver"/>
  </visual>
  <collision>
    <origin xyz="0.025 0.000205 -0.919071" rpy="0 0 0"/>
    <geometry>
      <mesh filename="file://$(find arm_description)/meshes/link_4_1.stl" scale="0.001 0.001 0.001"/>
    </geometry>
  </collision>
</link>

<joint name="Revolute 1" type="continuous">
  <origin xyz="0.0 0.0 0.13" rpy="0 0 0"/>
  <parent link="base_link"/>
  <child link="link_1_1"/>
  <axis xyz="0.0 0.0 1.0"/>
</joint>

<joint name="Revolute 2" type="continuous">
  <origin xyz="0.025 0.0 0.057" rpy="0 0 0"/>
  <parent link="link_1_1"/>
  <child link="link_2_1"/>
  <axis xyz="1.0 0.0 0.0"/>
</joint>

<joint name="Revolute 3" type="continuous">
  <origin xyz="-0.05 -0.000205 0.312621" rpy="0 0 0"/>
  <parent link="link_2_1"/>
  <child link="link_3_1"/>
  <axis xyz="1.0 0.0 0.0"/>
</joint>

<joint name="Revolute 4" type="continuous">
  <origin xyz="0.0 0.0 0.41945" rpy="0 0 0"/>
  <parent link="link_3_1"/>
  <child link="link_4_1"/>
  <axis xyz="1.0 0.0 0.0"/>
</joint>

</robot>
