<?xml version="1.0" ?>
<robot name="arm_hand" xmlns:xacro="http://www.ros.org/wiki/xacro">

<xacro:include filename="$(find arm_hand_description)/urdf/materials.xacro" />
<xacro:include filename="$(find arm_hand_description)/urdf/arm_hand.trans" />
<xacro:include filename="$(find arm_hand_description)/urdf/arm_hand.gazebo" />
<link name="base_link">
  <inertial>
    <origin xyz="0.0 -1.4925041259863438e-17 0.06499999999999999" rpy="0 0 0"/>
    <mass value="38.26875"/>
    <inertia ixx="0.125649" iyy="0.253212" izz="0.27107" ixy="-0.0" iyz="-0.0" ixz="-0.0"/>
  </inertial>
  <visual>
    <origin xyz="0 0 0" rpy="0 0 0"/>
    <geometry>
      <mesh filename="file://$(find arm_hand_description)/meshes/base_link.stl" scale="0.001 0.001 0.001"/>
    </geometry>
    <material name="silver"/>
  </visual>
  <collision>
    <origin xyz="0 0 0" rpy="0 0 0"/>
    <geometry>
      <mesh filename="file://$(find arm_hand_description)/meshes/base_link.stl" scale="0.001 0.001 0.001"/>
    </geometry>
  </collision>
</link>

<link name="link_1_1">
  <inertial>
    <origin xyz="0.0 -1.9172293647565634e-17 0.044466790992911065" rpy="0 0 0"/>
    <mass value="29.791045516659985"/>
    <inertia ixx="0.126725" iyy="0.177006" izz="0.260409" ixy="-0.0" iyz="-0.0" ixz="-0.0"/>
  </inertial>
  <visual>
    <origin xyz="-0.0 0.0 -0.13" rpy="0 0 0"/>
    <geometry>
      <mesh filename="file://$(find arm_hand_description)/meshes/link_1_1.stl" scale="0.001 0.001 0.001"/>
    </geometry>
    <material name="silver"/>
  </visual>
  <collision>
    <origin xyz="-0.0 0.0 -0.13" rpy="0 0 0"/>
    <geometry>
      <mesh filename="file://$(find arm_hand_description)/meshes/link_1_1.stl" scale="0.001 0.001 0.001"/>
    </geometry>
  </collision>
</link>

<link name="link_2_1">
  <inertial>
    <origin xyz="-0.02500000000000002 -0.00020598185767762477 0.15763545013473024" rpy="0 0 0"/>
    <mass value="5.4333462441733"/>
    <inertia ixx="0.05532" iyy="0.05572" izz="0.001864" ixy="0.0" iyz="-1e-06" ixz="-0.0"/>
  </inertial>
  <visual>
    <origin xyz="-0.025 0.0 -0.187" rpy="0 0 0"/>
    <geometry>
      <mesh filename="file://$(find arm_hand_description)/meshes/link_2_1.stl" scale="0.001 0.001 0.001"/>
    </geometry>
    <material name="silver"/>
  </visual>
  <collision>
    <origin xyz="-0.025 0.0 -0.187" rpy="0 0 0"/>
    <geometry>
      <mesh filename="file://$(find arm_hand_description)/meshes/link_2_1.stl" scale="0.001 0.001 0.001"/>
    </geometry>
  </collision>
</link>

<link name="link_3_1">
  <inertial>
    <origin xyz="-0.020000000000000018 1.8021706576167485e-07 0.20495556452816466" rpy="0 0 0"/>
    <mass value="5.602676995338639"/>
    <inertia ixx="0.093954" iyy="0.093948" izz="0.0015" ixy="0.0" iyz="0.0" ixz="0.0"/>
  </inertial>
  <visual>
    <origin xyz="0.025 0.000205 -0.499621" rpy="0 0 0"/>
    <geometry>
      <mesh filename="file://$(find arm_hand_description)/meshes/link_3_1.stl" scale="0.001 0.001 0.001"/>
    </geometry>
    <material name="silver"/>
  </visual>
  <collision>
    <origin xyz="0.025 0.000205 -0.499621" rpy="0 0 0"/>
    <geometry>
      <mesh filename="file://$(find arm_hand_description)/meshes/link_3_1.stl" scale="0.001 0.001 0.001"/>
    </geometry>
  </collision>
</link>

<link name="link_4_1">
  <inertial>
    <origin xyz="0.028999999999999984 1.8021706576387036e-07 0.04806556289092756" rpy="0 0 0"/>
    <mass value="3.001091821620516"/>
    <inertia ixx="0.004116" iyy="0.004106" izz="0.001692" ixy="-0.0" iyz="-0.0" ixz="0.0"/>
  </inertial>
  <visual>
    <origin xyz="0.025 0.000205 -0.919621" rpy="0 0 0"/>
    <geometry>
      <mesh filename="file://$(find arm_hand_description)/meshes/link_4_1.stl" scale="0.001 0.001 0.001"/>
    </geometry>
    <material name="silver"/>
  </visual>
  <collision>
    <origin xyz="0.025 0.000205 -0.919621" rpy="0 0 0"/>
    <geometry>
      <mesh filename="file://$(find arm_hand_description)/meshes/link_4_1.stl" scale="0.001 0.001 0.001"/>
    </geometry>
  </collision>
</link>

<link name="handbase_5_1">
  <inertial>
    <origin xyz="-1.8214596497756474e-17 1.802170657603196e-07 0.018609960542309345" rpy="0 0 0"/>
    <mass value="0.7459701857697482"/>
    <inertia ixx="0.000246" iyy="0.000246" izz="0.000307" ixy="-0.0" iyz="0.0" ixz="0.0"/>
  </inertial>
  <visual>
    <origin xyz="-0.004 0.000205 -1.024621" rpy="0 0 0"/>
    <geometry>
      <mesh filename="file://$(find arm_hand_description)/meshes/handbase_5_1.stl" scale="0.001 0.001 0.001"/>
    </geometry>
    <material name="silver"/>
  </visual>
  <collision>
    <origin xyz="-0.004 0.000205 -1.024621" rpy="0 0 0"/>
    <geometry>
      <mesh filename="file://$(find arm_hand_description)/meshes/handbase_5_1.stl" scale="0.001 0.001 0.001"/>
    </geometry>
  </collision>
</link>

<link name="finger1_6_1">
  <inertial>
    <origin xyz="-0.007499513941624035 -0.006437106950567203 0.039500770672345364" rpy="0 0 0"/>
    <mass value="0.06468846786272993"/>
    <inertia ixx="3.9e-05" iyy="3.9e-05" izz="2e-06" ixy="-0.0" iyz="6e-06" ixz="-0.0"/>
  </inertial>
  <visual>
    <origin xyz="-0.011535 -0.024759 -1.061824" rpy="0 0 0"/>
    <geometry>
      <mesh filename="file://$(find arm_hand_description)/meshes/finger1_6_1.stl" scale="0.001 0.001 0.001"/>
    </geometry>
    <material name="silver"/>
  </visual>
  <collision>
    <origin xyz="-0.011535 -0.024759 -1.061824" rpy="0 0 0"/>
    <geometry>
      <mesh filename="file://$(find arm_hand_description)/meshes/finger1_6_1.stl" scale="0.001 0.001 0.001"/>
    </geometry>
  </collision>
</link>

<link name="finger2_7_1">
  <inertial>
    <origin xyz="0.009324653009362697 -0.003276444371084373 0.039500770672345586" rpy="0 0 0"/>
    <mass value="0.06468846786272812"/>
    <inertia ixx="3.9e-05" iyy="3.9e-05" izz="2e-06" ixy="0.0" iyz="-3e-06" ixz="-5e-06"/>
  </inertial>
  <visual>
    <origin xyz="0.021387 0.006161 -1.061824" rpy="0 0 0"/>
    <geometry>
      <mesh filename="file://$(find arm_hand_description)/meshes/finger2_7_1.stl" scale="0.001 0.001 0.001"/>
    </geometry>
    <material name="silver"/>
  </visual>
  <collision>
    <origin xyz="0.021387 0.006161 -1.061824" rpy="0 0 0"/>
    <geometry>
      <mesh filename="file://$(find arm_hand_description)/meshes/finger2_7_1.stl" scale="0.001 0.001 0.001"/>
    </geometry>
  </collision>
</link>

<link name="finger3_8_1">
  <inertial>
    <origin xyz="-0.009758139067738657 -0.004026908027151965 0.039500770672345364" rpy="0 0 0"/>
    <mass value="0.06468846786272814"/>
    <inertia ixx="3.9e-05" iyy="3.9e-05" izz="2e-06" ixy="-0.0" iyz="-3e-06" ixz="5e-06"/>
  </inertial>
  <visual>
    <origin xyz="-0.029785 0.005472 -1.061824" rpy="0 0 0"/>
    <geometry>
      <mesh filename="file://$(find arm_hand_description)/meshes/finger3_8_1.stl" scale="0.001 0.001 0.001"/>
    </geometry>
    <material name="silver"/>
  </visual>
  <collision>
    <origin xyz="-0.029785 0.005472 -1.061824" rpy="0 0 0"/>
    <geometry>
      <mesh filename="file://$(find arm_hand_description)/meshes/finger3_8_1.stl" scale="0.001 0.001 0.001"/>
    </geometry>
  </collision>
</link>

<joint name="Revolute 1" type="continuous">
  <origin xyz="0.0 0.0 0.13" rpy="0 0 0"/>
  <parent link="base_link"/>
  <child link="link_1_1"/>
  <axis xyz="0.0 0.0 1.0"/>
</joint>

<joint name="Revolute 2" type="continuous">
  <origin xyz="0.025 0.0 0.057" rpy="0 0 0"/>
  <parent link="link_1_1"/>
  <child link="link_2_1"/>
  <axis xyz="1.0 0.0 0.0"/>
</joint>

<joint name="Revolute 3" type="continuous">
  <origin xyz="-0.05 -0.000205 0.312621" rpy="0 0 0"/>
  <parent link="link_2_1"/>
  <child link="link_3_1"/>
  <axis xyz="-1.0 0.0 0.0"/>
</joint>

<joint name="Revolute 4" type="continuous">
  <origin xyz="0.0 0.0 0.42" rpy="0 0 0"/>
  <parent link="link_3_1"/>
  <child link="link_4_1"/>
  <axis xyz="-1.0 0.0 0.0"/>
</joint>

<joint name="Revolute 5" type="continuous">
  <origin xyz="0.029 0.0 0.105" rpy="0 0 0"/>
  <parent link="link_4_1"/>
  <child link="handbase_5_1"/>
  <axis xyz="0.0 0.0 1.0"/>
</joint>

<joint name="Revolute 6" type="continuous">
  <origin xyz="0.007535 0.024964 0.037203" rpy="0 0 0"/>
  <parent link="handbase_5_1"/>
  <child link="finger1_6_1"/>
  <axis xyz="1.0 0.0 0.0"/>
</joint>

<joint name="Revolute 7" type="continuous">
  <origin xyz="-0.025387 -0.005956 0.037203" rpy="0 0 0"/>
  <parent link="handbase_5_1"/>
  <child link="finger2_7_1"/>
  <axis xyz="-0.5 0.866025 0.0"/>
</joint>

<joint name="Revolute 8" type="continuous">
  <origin xyz="0.025785 -0.005267 0.037203" rpy="0 0 0"/>
  <parent link="handbase_5_1"/>
  <child link="finger3_8_1"/>
  <axis xyz="-0.5 -0.866025 0.0"/>
</joint>

</robot>
